<?xml version="1.0" encoding="utf-8"?>
<!-- =================================================================================== -->
<!-- |    This document was autogenerated by xacro from gudel_tmf2_single.xacro        | -->
<!-- |    EDITING THIS FILE BY HAND IS NOT RECOMMENDED                                 | -->
<!-- =================================================================================== -->
<robot name="gudel_tmf2_single">
  <!-- link list -->
  <link name="base_link">
    <visual>
      <origin rpy="0 0 0" xyz="0 0 0"/>
      <geometry>
        <mesh filename="package://twc_support/CAD/rail/gudel_tmf2/urdf/visual/base_link.dae"/>
      </geometry>
    </visual>
    <collision>
      <origin rpy="0 0 0" xyz="0 0 0"/>
      <geometry>
        <mesh filename="package://twc_support/CAD/rail/gudel_tmf2/urdf/visual/base_link.dae"/>
      </geometry>
    </collision>
  </link>
  <link name="link_1">
    <visual>
      <origin rpy="0 0 0" xyz="0 0 0"/>
      <geometry>
        <mesh filename="package://twc_support/CAD/rail/gudel_tmf2/urdf/visual/link_1.dae"/>
      </geometry>
    </visual>
    <collision>
      <origin rpy="0 0 0" xyz="0 0 0"/>
      <geometry>
        <mesh filename="package://twc_support/CAD/rail/gudel_tmf2/urdf/visual/link_1.dae"/>
      </geometry>
    </collision>
  </link>
  <link name="tool0"/>
  <!-- end of link list -->
  <!-- joint list -->
  <joint name="joint_1" type="prismatic">
    <origin rpy="0 0 0" xyz="0 0 0"/>
    <parent link="base_link"/>
    <child link="link_1"/>
    <axis xyz="0 1 0"/>
    <limit effort="0" lower="0" upper="10" velocity="2.5"/>
  </joint>
  <joint name="joint_1_tool0" type="fixed">
    <origin rpy="0 0 0" xyz="0.125 0 0.340"/>
    <parent link="link_1"/>
    <child link="tool0"/>
  </joint>
  <!-- end of joint list -->
</robot>

