<?xml version="1.0" encoding="utf-8"?>
<!-- =================================================================================== -->
<!-- |    This document was autogenerated by xacro from irbpa250_d1000.xacro           | -->
<!-- |    EDITING THIS FILE BY HAND IS NOT RECOMMENDED                                 | -->
<!-- =================================================================================== -->
<robot name="abb_irbpa250_d1000">
  <!-- link list -->
  <link name="base_link">
    <visual>
      <origin rpy="0 0 0" xyz="0 0 0"/>
      <geometry>
        <mesh filename="package://twc_support/CAD/robot/abb_irbpa250_d1000/urdf/visual/base_link.dae"/>
      </geometry>
    </visual>
    <collision>
      <origin rpy="0 0 0" xyz="0 0 0"/>
      <geometry>
        <mesh filename="package://twc_support/CAD/robot/abb_irbpa250_d1000/urdf/visual/base_link.dae"/>
      </geometry>
    </collision>
  </link>
  <link name="link_1">
    <visual>
      <origin rpy="0 0 0" xyz="0 0 0"/>
      <geometry>
        <mesh filename="package://twc_support/CAD/robot/abb_irbpa250_d1000/urdf/visual/link_1.dae"/>
      </geometry>
    </visual>
    <collision>
      <origin rpy="0 0 0" xyz="0 0 0"/>
      <geometry>
        <mesh filename="package://twc_support/CAD/robot/abb_irbpa250_d1000/urdf/visual/link_1.dae"/>
      </geometry>
    </collision>
  </link>
  <link name="link_2">
    <visual>
      <origin rpy="0 0 0" xyz="0 0 0"/>
      <geometry>
        <mesh filename="package://twc_support/CAD/robot/abb_irbpa250_d1000/urdf/visual/link_2.dae"/>
      </geometry>
    </visual>
    <collision>
      <origin rpy="0 0 0" xyz="0 0 0"/>
      <geometry>
        <mesh filename="package://twc_support/CAD/robot/abb_irbpa250_d1000/urdf/visual/link_2.dae"/>
      </geometry>
    </collision>
  </link>
  <link name="tool0"/>
  <!-- end of link list -->
  <!-- joint list -->
  <joint name="base_joint" type="revolute">
    <origin rpy="0 0 0" xyz="0.733 0 1.020"/>
    <parent link="base_link"/>
    <child link="link_1"/>
    <axis xyz="1 0 0"/>
    <limit effort="0" lower="-6.28319" upper="6.28319" velocity="1.4834"/>
  </joint>
  <joint name="joint_1" type="revolute">
    <origin rpy="0 0 0" xyz="-0.733 0 0"/>
    <parent link="link_1"/>
    <child link="link_2"/>
    <axis xyz="0 0 1"/>
    <limit effort="0" lower="-6.28319" upper="6.28319" velocity="1.4834"/>
  </joint>
  <joint name="joint_2_tool0" type="fixed">
    <origin rpy="0 0 0" xyz="0 0 0.10487"/>
    <parent link="link_2"/>
    <child link="tool0"/>
  </joint>
  <!-- end of joint list -->
</robot>

