<?xml version="1.0" ?>
<!-- =================================================================================== -->
<!-- |    This document was autogenerated by xacro from workcell_positioner.xacro      | -->
<!-- |    EDITING THIS FILE BY HAND IS NOT RECOMMENDED                                 | -->
<!-- =================================================================================== -->
<robot name="tesseract_workcell_positioner">
  <!-- link list -->
  <link name="ati_qc110m_base_link">
    <visual>
      <origin rpy="0 0 0" xyz="0 0 0"/>
      <geometry>
        <mesh filename="package://twc_support/CAD/eoat/ati_qc110m/urdf/visual/base_link.dae"/>
      </geometry>
    </visual>
    <collision>
      <origin rpy="0 0 0" xyz="0 0 0"/>
      <geometry>
        <mesh filename="package://twc_support/CAD/eoat/ati_qc110m/urdf/visual/base_link.dae"/>
      </geometry>
    </collision>
  </link>
  <link name="ati_qc110m_tool0"/>
  <!-- end of link list -->
  <!-- joint list -->
  <joint name="ati_qc110m_base_link_tool0" type="fixed">
    <origin rpy="0 0 0" xyz="0 0 0.05537"/>
    <parent link="ati_qc110m_base_link"/>
    <child link="ati_qc110m_tool0"/>
  </joint>
  <!-- end of joint list -->
  <!-- link list -->
  <link name="ati_qc110f_base_link">
    <visual>
      <origin rpy="0 0 0" xyz="0 0 0"/>
      <geometry>
        <mesh filename="package://twc_support/CAD/eoat/ati_qc110f/urdf/visual/base_link.dae"/>
      </geometry>
    </visual>
    <collision>
      <origin rpy="0 0 0" xyz="0 0 0"/>
      <geometry>
        <mesh filename="package://twc_support/CAD/eoat/ati_qc110f/urdf/visual/base_link.dae"/>
      </geometry>
    </collision>
  </link>
  <link name="ati_qc110f_tool0"/>
  <!-- end of link list -->
  <!-- joint list -->
  <joint name="ati_qc110f_base_link_tool0" type="fixed">
    <origin rpy="0 0 0" xyz="0 0 0.03754"/>
    <parent link="ati_qc110f_base_link"/>
    <child link="ati_qc110f_tool0"/>
  </joint>
  <!-- end of joint list -->
  <!-- link list -->
  <link name="ati_stand_base_link">
    <visual>
      <origin rpy="0 0 0" xyz="0 0 0"/>
      <geometry>
        <mesh filename="package://twc_support/CAD/eoat/ati_9120_stand/urdf/visual/base_link.dae"/>
      </geometry>
    </visual>
    <collision>
      <origin rpy="0 0 0" xyz="0 0 0"/>
      <geometry>
        <mesh filename="package://twc_support/CAD/eoat/ati_9120_stand/urdf/visual/base_link.dae"/>
      </geometry>
    </collision>
  </link>
  <link name="ati_stand_tool0"/>
  <link name="ati_stand_tool1"/>
  <!-- end of link list -->
  <!-- joint list -->
  <joint name="ati_stand_base_link_tool0" type="fixed">
    <origin rpy="0 1.5708 0" xyz="0.150 0.275 1.2"/>
    <parent link="ati_stand_base_link"/>
    <child link="ati_stand_tool0"/>
  </joint>
  <joint name="ati_stand_base_link_tool1" type="fixed">
    <origin rpy="0 1.5708 0" xyz="0.150 -0.275 1.2"/>
    <parent link="ati_stand_base_link"/>
    <child link="ati_stand_tool1"/>
  </joint>
  <!-- end of joint list -->
  <!-- link list -->
  <link name="ati_dock1_base_link">
    <visual>
      <origin rpy="0 0 0" xyz="0 0 0"/>
      <geometry>
        <mesh filename="package://twc_support/CAD/eoat/ati_9120_tsm_mmb_8432/urdf/visual/base_link.dae"/>
      </geometry>
    </visual>
    <collision>
      <origin rpy="0 0 0" xyz="0 0 0"/>
      <geometry>
        <mesh filename="package://twc_support/CAD/eoat/ati_9120_tsm_mmb_8432/urdf/visual/base_link.dae"/>
      </geometry>
    </collision>
  </link>
  <link name="ati_dock1_tool0"/>
  <!-- end of link list -->
  <!-- joint list -->
  <joint name="ati_dock1_base_link_tool0" type="fixed">
    <origin rpy="0 0 0" xyz="0 0.05398 0.01524"/>
    <parent link="ati_dock1_base_link"/>
    <child link="ati_dock1_tool0"/>
  </joint>
  <!-- end of joint list -->
  <!-- link list -->
  <link name="ati_dock2_base_link">
    <visual>
      <origin rpy="0 0 0" xyz="0 0 0"/>
      <geometry>
        <mesh filename="package://twc_support/CAD/eoat/ati_9120_tsm_mmb_8432/urdf/visual/base_link.dae"/>
      </geometry>
    </visual>
    <collision>
      <origin rpy="0 0 0" xyz="0 0 0"/>
      <geometry>
        <mesh filename="package://twc_support/CAD/eoat/ati_9120_tsm_mmb_8432/urdf/visual/base_link.dae"/>
      </geometry>
    </collision>
  </link>
  <link name="ati_dock2_tool0"/>
  <!-- end of link list -->
  <!-- joint list -->
  <joint name="ati_dock2_base_link_tool0" type="fixed">
    <origin rpy="0 0 0" xyz="0 0.05398 0.01524"/>
    <parent link="ati_dock2_base_link"/>
    <child link="ati_dock2_tool0"/>
  </joint>
  <!-- end of joint list -->
  <!-- link list -->
  <link name="ati_dock_base_link">
    <visual>
      <origin rpy="0 0 0" xyz="0 0 0"/>
      <geometry>
        <mesh filename="package://twc_support/CAD/eoat/ati_9120_tsm_hbq_9224/urdf/visual/base_link.dae"/>
      </geometry>
    </visual>
    <collision>
      <origin rpy="0 0 0" xyz="0 0 0"/>
      <geometry>
        <mesh filename="package://twc_support/CAD/eoat/ati_9120_tsm_hbq_9224/urdf/visual/base_link.dae"/>
      </geometry>
    </collision>
  </link>
  <link name="ati_dock_tool0"/>
  <!-- end of link list -->
  <!-- joint list -->
  <joint name="ati_dock_base_link_tool0" type="fixed">
    <origin rpy="0 0 0" xyz="0 0 0.01778"/>
    <parent link="ati_dock_base_link"/>
    <child link="ati_dock_tool0"/>
  </joint>
  <!-- end of joint list -->
  <!-- link list -->
  <link name="pushcorp_afd620_base_link">
    <visual>
      <origin rpy="0 0 0" xyz="0 0 0"/>
      <geometry>
        <mesh filename="package://twc_support/CAD/eoat/pushcorp_afd620/urdf/visual/base_link.dae"/>
      </geometry>
    </visual>
    <collision>
      <origin rpy="0 0 0" xyz="0 0 0"/>
      <geometry>
        <mesh filename="package://twc_support/CAD/eoat/pushcorp_afd620/urdf/visual/base_link.dae"/>
      </geometry>
    </collision>
  </link>
  <link name="pushcorp_afd620_link_1">
    <visual>
      <origin rpy="0 0 0" xyz="0 0 0"/>
      <geometry>
        <mesh filename="package://twc_support/CAD/eoat/pushcorp_afd620/urdf/visual/link_1.dae"/>
      </geometry>
    </visual>
    <collision>
      <origin rpy="0 0 0" xyz="0 0 0"/>
      <geometry>
        <mesh filename="package://twc_support/CAD/eoat/pushcorp_afd620/urdf/visual/link_1.dae"/>
      </geometry>
    </collision>
  </link>
  <link name="pushcorp_afd620_tool0"/>
  <!-- end of link list -->
  <!-- joint list -->
  <joint name="pushcorp_afd620_joint_1" type="prismatic">
    <origin rpy="0 0 0" xyz="0 0 0.08471"/>
    <parent link="pushcorp_afd620_base_link"/>
    <child link="pushcorp_afd620_link_1"/>
    <axis xyz="1 0 0"/>
    <limit effort="0" lower="-0.0254" upper="0.0254" velocity="1.4834"/>
  </joint>
  <joint name="pushcorp_afd620_joint_1_tool0" type="fixed">
    <origin rpy="0 0 0" xyz="0 0 0.03747"/>
    <parent link="pushcorp_afd620_link_1"/>
    <child link="pushcorp_afd620_tool0"/>
  </joint>
  <!-- end of joint list -->
  <!-- link list -->
  <link name="pushcorp_stc1015_base_link">
    <visual>
      <origin rpy="0 0 0" xyz="0 0 0"/>
      <geometry>
        <mesh filename="package://twc_support/CAD/eoat/pushcorp_stc1015/urdf/visual/base_link.dae"/>
      </geometry>
    </visual>
    <collision>
      <origin rpy="0 0 0" xyz="0 0 0"/>
      <geometry>
        <mesh filename="package://twc_support/CAD/eoat/pushcorp_stc1015/urdf/visual/base_link.dae"/>
      </geometry>
    </collision>
  </link>
  <link name="pushcorp_stc1015_tool0"/>
  <!-- end of link list -->
  <!-- joint list -->
  <joint name="pushcorp_stc1015_joint_tool0" type="fixed">
    <origin rpy="0 1.57 0" xyz="0.225 0 0.081695"/>
    <parent link="pushcorp_stc1015_base_link"/>
    <child link="pushcorp_stc1015_tool0"/>
  </joint>
  <!-- end of joint list -->
  <!-- link list -->
  <link name="positioner_base_link">
    <visual>
      <origin rpy="0 0 0" xyz="0 0 0"/>
      <geometry>
        <mesh filename="package://twc_support/CAD/robot/abb_irbpa250_d1000/urdf/visual/base_link.dae"/>
      </geometry>
    </visual>
    <collision>
      <origin rpy="0 0 0" xyz="0 0 0"/>
      <geometry>
        <mesh filename="package://twc_support/CAD/robot/abb_irbpa250_d1000/urdf/visual/base_link.dae"/>
      </geometry>
    </collision>
  </link>
  <link name="positioner_link_1">
    <visual>
      <origin rpy="0 0 0" xyz="0 0 0"/>
      <geometry>
        <mesh filename="package://twc_support/CAD/robot/abb_irbpa250_d1000/urdf/visual/link_1.dae"/>
      </geometry>
    </visual>
    <collision>
      <origin rpy="0 0 0" xyz="0 0 0"/>
      <geometry>
        <mesh filename="package://twc_support/CAD/robot/abb_irbpa250_d1000/urdf/visual/link_1.dae"/>
      </geometry>
    </collision>
  </link>
  <link name="positioner_link_2">
    <visual>
      <origin rpy="0 0 0" xyz="0 0 0"/>
      <geometry>
        <mesh filename="package://twc_support/CAD/robot/abb_irbpa250_d1000/urdf/visual/link_2.dae"/>
      </geometry>
    </visual>
    <collision>
      <origin rpy="0 0 0" xyz="0 0 0"/>
      <geometry>
        <mesh filename="package://twc_support/CAD/robot/abb_irbpa250_d1000/urdf/visual/link_2.dae"/>
      </geometry>
    </collision>
  </link>
  <link name="positioner_tool0"/>
  <!-- end of link list -->
  <!-- joint list -->
  <joint name="positioner_base_joint" type="revolute">
    <origin rpy="0 0 0" xyz="0.733 0 1.020"/>
    <parent link="positioner_base_link"/>
    <child link="positioner_link_1"/>
    <axis xyz="1 0 0"/>
    <limit effort="0" lower="-6.28319" upper="6.28319" velocity="1.4834"/>
  </joint>
  <joint name="positioner_joint_1" type="revolute">
    <origin rpy="0 0 0" xyz="-0.733 0 0"/>
    <parent link="positioner_link_1"/>
    <child link="positioner_link_2"/>
    <axis xyz="0 0 1"/>
    <limit effort="0" lower="-6.28319" upper="6.28319" velocity="1.4834"/>
  </joint>
  <joint name="positioner_joint_2_tool0" type="fixed">
    <origin rpy="0 0 0" xyz="0 0 0.10487"/>
    <parent link="positioner_link_2"/>
    <child link="positioner_tool0"/>
  </joint>
  <!-- end of joint list -->
  <!-- link list -->
  <link name="st_base_link">
    <visual>
      <origin rpy="0 0 0" xyz="0 0 0"/>
      <geometry>
        <mesh filename="package://twc_support/CAD/eoat/bt30_sander/urdf/visual/base_link.dae"/>
      </geometry>
    </visual>
    <collision>
      <origin rpy="0 0 0" xyz="0 0 0"/>
      <geometry>
        <mesh filename="package://twc_support/CAD/eoat/bt30_sander/urdf/visual/base_link.dae"/>
      </geometry>
    </collision>
  </link>
  <link name="st_tool0"/>
  <!-- end of link list -->
  <!-- joint list -->
  <joint name="st_joint_tool0" type="fixed">
    <origin rpy="0 0 0" xyz="0 0 0.07328"/>
    <parent link="st_base_link"/>
    <child link="st_tool0"/>
  </joint>
  <!-- end of joint list -->
  <!-- link list -->
  <link name="robot_base_link">
    <collision name="collision">
      <geometry>
        <mesh filename="package://twc_support/CAD/robot/abb_irb4600_60_205/urdf/collision/base_link.stl"/>
      </geometry>
    </collision>
    <visual name="visual">
      <geometry>
        <mesh filename="package://twc_support/CAD/robot/abb_irb4600_60_205/urdf/visual/base_link.dae"/>
      </geometry>
      <material name="yellow">
        <color rgba="1 1 0 1"/>
      </material>
    </visual>
  </link>
  <link name="robot_link_1">
    <collision name="collision">
      <geometry>
        <mesh filename="package://twc_support/CAD/robot/abb_irb4600_60_205/urdf/collision/link_1.stl"/>
      </geometry>
    </collision>
    <visual name="visual">
      <geometry>
        <mesh filename="package://twc_support/CAD/robot/abb_irb4600_60_205/urdf/visual/link_1.dae"/>
      </geometry>
      <material name="yellow"/>
    </visual>
  </link>
  <link name="robot_link_2">
    <collision name="collision">
      <geometry>
        <mesh filename="package://twc_support/CAD/robot/abb_irb4600_60_205/urdf/collision/link_2.stl"/>
      </geometry>
    </collision>
    <visual name="visual">
      <geometry>
        <mesh filename="package://twc_support/CAD/robot/abb_irb4600_60_205/urdf/visual/link_2.dae"/>
      </geometry>
      <material name="yellow"/>
    </visual>
  </link>
  <link name="robot_link_3">
    <collision name="collision">
      <geometry>
        <mesh filename="package://twc_support/CAD/robot/abb_irb4600_60_205/urdf/collision/link_3.stl"/>
      </geometry>
    </collision>
    <visual name="visual">
      <geometry>
        <mesh filename="package://twc_support/CAD/robot/abb_irb4600_60_205/urdf/visual/link_3.dae"/>
      </geometry>
      <material name="yellow"/>
    </visual>
  </link>
  <link name="robot_link_4">
    <collision name="collision">
      <geometry>
        <mesh filename="package://twc_support/CAD/robot/abb_irb4600_60_205/urdf/collision/link_4.stl"/>
      </geometry>
    </collision>
    <visual name="visual">
      <geometry>
        <mesh filename="package://twc_support/CAD/robot/abb_irb4600_60_205/urdf/visual/link_4.dae"/>
      </geometry>
      <material name="yellow"/>
    </visual>
  </link>
  <link name="robot_link_5">
    <collision name="collision">
      <geometry>
        <mesh filename="package://twc_support/CAD/robot/abb_irb4600_60_205/urdf/collision/link_5.stl"/>
      </geometry>
    </collision>
    <visual name="visual">
      <geometry>
        <mesh filename="package://twc_support/CAD/robot/abb_irb4600_60_205/urdf/visual/link_5.dae"/>
      </geometry>
      <material name="yellow"/>
    </visual>
  </link>
  <link name="robot_link_6">
    <collision name="collision">
      <geometry>
        <mesh filename="package://twc_support/CAD/robot/abb_irb4600_60_205/urdf/collision/link_6.stl"/>
      </geometry>
    </collision>
    <visual name="visual">
      <geometry>
        <mesh filename="package://twc_support/CAD/robot/abb_irb4600_60_205/urdf/visual/link_6.dae"/>
      </geometry>
      <material name="yellow"/>
    </visual>
  </link>
  <link name="robot_tool0"/>
  <!-- end of link list -->
  <!-- joint list -->
  <joint name="robot_joint_1" type="revolute">
    <origin rpy="0 0 0" xyz="0 0 0.495"/>
    <axis xyz="0 0 1"/>
    <parent link="robot_base_link"/>
    <child link="robot_link_1"/>
    <limit effort="0" lower="-3.141" upper="3.141" velocity="3.054"/>
  </joint>
  <joint name="robot_joint_2" type="revolute">
    <origin rpy="0 0 0" xyz="0.175 0 0"/>
    <axis xyz="0 1 0"/>
    <parent link="robot_link_1"/>
    <child link="robot_link_2"/>
    <limit effort="0" lower="-1.570" upper="2.617" velocity="3.054"/>
  </joint>
  <joint name="robot_joint_3" type="revolute">
    <origin rpy="0 0 0" xyz="0 0 0.9"/>
    <axis xyz="0 1 0"/>
    <parent link="robot_link_2"/>
    <child link="robot_link_3"/>
    <limit effort="0" lower="-3.141" upper="1.308" velocity="3.054"/>
  </joint>
  <joint name="robot_joint_4" type="revolute">
    <origin rpy="0 0 0" xyz="0 0 0.175"/>
    <axis xyz="1 0 0"/>
    <parent link="robot_link_3"/>
    <child link="robot_link_4"/>
    <limit effort="0" lower="-6.981" upper="6.981" velocity="4.363"/>
  </joint>
  <joint name="robot_joint_5" type="revolute">
    <origin rpy="0 0 0" xyz="0.960 0 0 "/>
    <axis xyz="0 1 0"/>
    <parent link="robot_link_4"/>
    <child link="robot_link_5"/>
    <limit effort="0" lower="-2.181" upper="2.094" velocity="4.363"/>
  </joint>
  <joint name="robot_joint_6" type="revolute">
    <origin rpy="0 0 0" xyz="0 0 0 "/>
    <axis xyz="1 0 0"/>
    <parent link="robot_link_5"/>
    <child link="robot_link_6"/>
    <limit effort="0" lower="-6.981" upper="6.981" velocity="6.283"/>
  </joint>
  <joint name="robot_joint_6-tool0" type="fixed">
    <parent link="robot_link_6"/>
    <child link="robot_tool0"/>
    <origin rpy="0 1.57079632679 0" xyz="0.135 0 0"/>
  </joint>
  <!-- end of joint list -->
  <!-- ROS base_link to ABB World Coordinates transform -->
  <link name="robot_base"/>
  <joint name="robot_base_link-base" type="fixed">
    <origin rpy="0 0 0" xyz="0 0 0"/>
    <parent link="robot_base_link"/>
    <child link="robot_base"/>
  </joint>
  <!-- link list -->
  <link name="pedestal_base_link">
    <visual>
      <origin rpy="0 0 0" xyz="0 0 0"/>
      <geometry>
        <mesh filename="package://twc_support/CAD/pedestal/pedestal_750mm/urdf/visual/base_link.dae"/>
      </geometry>
    </visual>
    <collision>
      <origin rpy="0 0 0" xyz="0 0 0"/>
      <geometry>
        <mesh filename="package://twc_support/CAD/pedestal/pedestal_750mm/urdf/visual/base_link.dae"/>
      </geometry>
    </collision>
  </link>
  <link name="pedestal_tool0"/>
  <!-- end of link list -->
  <!-- joint list -->
  <joint name="pedestal_base_link_tool0" type="fixed">
    <origin rpy="0 0 0" xyz="0 0 0.5"/>
    <parent link="pedestal_base_link"/>
    <child link="pedestal_tool0"/>
  </joint>
  <!-- end of joint list -->
  <!-- link list -->
  <link name="fence_panel1_base_link">
    <visual>
      <origin rpy="0 0 0" xyz="0 0 0"/>
      <geometry>
        <mesh filename="package://twc_support/CAD/fence/panel_3m_2m_solid/urdf/visual/base_link.dae"/>
      </geometry>
    </visual>
    <collision>
      <origin rpy="0 0 0" xyz="0 0 0"/>
      <geometry>
        <mesh filename="package://twc_support/CAD/fence/panel_3m_2m_solid/urdf/visual/base_link.dae"/>
      </geometry>
    </collision>
  </link>
  <link name="fence_panel1_tool0"/>
  <joint name="fence_panel1_joint_1" type="fixed">
    <origin rpy="0 0 0" xyz="2.0 0 0"/>
    <parent link="fence_panel1_base_link"/>
    <child link="fence_panel1_tool0"/>
  </joint>
  <!-- link list -->
  <link name="fence_panel2_base_link">
    <visual>
      <origin rpy="0 0 0" xyz="0 0 0"/>
      <geometry>
        <mesh filename="package://twc_support/CAD/fence/panel_3m_2m_solid/urdf/visual/base_link.dae"/>
      </geometry>
    </visual>
    <collision>
      <origin rpy="0 0 0" xyz="0 0 0"/>
      <geometry>
        <mesh filename="package://twc_support/CAD/fence/panel_3m_2m_solid/urdf/visual/base_link.dae"/>
      </geometry>
    </collision>
  </link>
  <link name="fence_panel2_tool0"/>
  <joint name="fence_panel2_joint_1" type="fixed">
    <origin rpy="0 0 0" xyz="2.0 0 0"/>
    <parent link="fence_panel2_base_link"/>
    <child link="fence_panel2_tool0"/>
  </joint>
  <!-- link list -->
  <link name="fence_panel3_base_link">
    <visual>
      <origin rpy="0 0 0" xyz="0 0 0"/>
      <geometry>
        <mesh filename="package://twc_support/CAD/fence/panel_3m_2m_solid/urdf/visual/base_link.dae"/>
      </geometry>
    </visual>
    <collision>
      <origin rpy="0 0 0" xyz="0 0 0"/>
      <geometry>
        <mesh filename="package://twc_support/CAD/fence/panel_3m_2m_solid/urdf/visual/base_link.dae"/>
      </geometry>
    </collision>
  </link>
  <link name="fence_panel3_tool0"/>
  <joint name="fence_panel3_joint_1" type="fixed">
    <origin rpy="0 0 0" xyz="2.0 0 0"/>
    <parent link="fence_panel3_base_link"/>
    <child link="fence_panel3_tool0"/>
  </joint>
  <!-- link list -->
  <link name="fence_panel4_base_link">
    <visual>
      <origin rpy="0 0 0" xyz="0 0 0"/>
      <geometry>
        <mesh filename="package://twc_support/CAD/fence/panel_3m_2m_solid/urdf/visual/base_link.dae"/>
      </geometry>
    </visual>
    <collision>
      <origin rpy="0 0 0" xyz="0 0 0"/>
      <geometry>
        <mesh filename="package://twc_support/CAD/fence/panel_3m_2m_solid/urdf/visual/base_link.dae"/>
      </geometry>
    </collision>
  </link>
  <link name="fence_panel4_tool0"/>
  <joint name="fence_panel4_joint_1" type="fixed">
    <origin rpy="0 0 0" xyz="2.0 0 0"/>
    <parent link="fence_panel4_base_link"/>
    <child link="fence_panel4_tool0"/>
  </joint>
  <!-- link list -->
  <link name="fence_panel5_base_link">
    <visual>
      <origin rpy="0 0 0" xyz="0 0 0"/>
      <geometry>
        <mesh filename="package://twc_support/CAD/fence/panel_3m_2m_solid/urdf/visual/base_link.dae"/>
      </geometry>
    </visual>
    <collision>
      <origin rpy="0 0 0" xyz="0 0 0"/>
      <geometry>
        <mesh filename="package://twc_support/CAD/fence/panel_3m_2m_solid/urdf/visual/base_link.dae"/>
      </geometry>
    </collision>
  </link>
  <link name="fence_panel5_tool0"/>
  <joint name="fence_panel5_joint_1" type="fixed">
    <origin rpy="0 0 0" xyz="2.0 0 0"/>
    <parent link="fence_panel5_base_link"/>
    <child link="fence_panel5_tool0"/>
  </joint>
  <!-- link list -->
  <link name="fence_panel6_base_link">
    <visual>
      <origin rpy="0 0 0" xyz="0 0 0"/>
      <geometry>
        <mesh filename="package://twc_support/CAD/fence/panel_3m_2m_solid/urdf/visual/base_link.dae"/>
      </geometry>
    </visual>
    <collision>
      <origin rpy="0 0 0" xyz="0 0 0"/>
      <geometry>
        <mesh filename="package://twc_support/CAD/fence/panel_3m_2m_solid/urdf/visual/base_link.dae"/>
      </geometry>
    </collision>
  </link>
  <link name="fence_panel6_tool0"/>
  <joint name="fence_panel6_joint_1" type="fixed">
    <origin rpy="0 0 0" xyz="2.0 0 0"/>
    <parent link="fence_panel6_base_link"/>
    <child link="fence_panel6_tool0"/>
  </joint>
  <link name="logo_base_link">
    <visual>
      <origin rpy="0 0 0" xyz="-0.125 -0.05 0.01"/>
      <geometry>
        <box size="1.25 0.6 0.02"/>
      </geometry>
      <material name="WhiteLogo">
        <color rgba="1.0 1.0 1.0 1.0"/>
      </material>
    </visual>
    <visual>
      <origin rpy="0 0 0" xyz="0 0 0.02"/>
      <geometry>
        <mesh filename="package://twc_support/CAD/logo/ros_industrial/urdf/visual/ros_industrial_logo.dae"/>
      </geometry>
    </visual>
    <collision>
      <origin rpy="0 0 0" xyz="0 0 0"/>
      <geometry>
        <box size="1 1 0.03"/>
      </geometry>
    </collision>
  </link>
  <!-- link list -->
  <link name="world"/>
  <link name="tool_dock0"/>
  <link name="part_link">
    <visual>
      <origin rpy="0 0 0" xyz="0 0 0"/>
      <geometry>
        <mesh filename="package://twc_support/meshes/fuselage_part.dae"/>
      </geometry>
    </visual>
    <collision>
      <origin rpy="0 0 0" xyz="0 0 0"/>
      <geometry>
        <mesh filename="package://twc_support/meshes/fuselage_part.ply"/>
      </geometry>
    </collision>
  </link>
  <!-- joint list -->
  <joint name="world_positioner_joint" type="fixed">
    <origin rpy="0 0 1.5708" xyz="0 0.25 0"/>
    <parent link="world"/>
    <child link="positioner_base_link"/>
  </joint>
  <joint name="world_pedestal_joint" type="fixed">
    <origin rpy="0 0 1.5708" xyz="0 -1 0"/>
    <parent link="world"/>
    <child link="pedestal_base_link"/>
  </joint>
  <joint name="pedestal_robot_joint" type="fixed">
    <origin rpy="0 0 0" xyz="0 0 0"/>
    <parent link="pedestal_tool0"/>
    <child link="robot_base_link"/>
  </joint>
  <joint name="world_ati_stand_joint" type="fixed">
    <origin rpy="0 0 1.5708" xyz="1.25 -1.25 0"/>
    <parent link="world"/>
    <child link="ati_stand_base_link"/>
  </joint>
  <joint name="ati_stand_dock1_joint" type="fixed">
    <origin rpy="0 0 0" xyz="0 0 0"/>
    <parent link="ati_stand_tool0"/>
    <child link="ati_dock1_base_link"/>
  </joint>
  <joint name="ati_stand_dock2_joint" type="fixed">
    <origin rpy="0 0 0" xyz="0 0 0"/>
    <parent link="ati_stand_tool1"/>
    <child link="ati_dock2_base_link"/>
  </joint>
  <joint name="robot_ati_m_joint" type="fixed">
    <!--      <origin xyz="0 0 0.05" rpy="0 0.785398 3.14159" />-->
    <origin rpy="0 0 0" xyz="0 0 0"/>
    <parent link="robot_tool0"/>
    <child link="ati_qc110m_base_link"/>
  </joint>
  <joint name="world_tool_dock0_joint" type="fixed">
    <origin rpy="-1.5708 -1.5708 -3.14" xyz="-1 -1 1"/>
    <parent link="world"/>
    <child link="tool_dock0"/>
  </joint>
  <!--<joint name="${prefix}tool_dock0_ati_f_joint" type="fixed">
      <origin xyz="0 0 0" rpy="0 0 0" />
      <parent link="${prefix}tool_dock0" />
      <child link="${prefix}ati_f_base_link" />
    </joint>-->
  <joint name="robot_ati_f_joint" type="fixed">
    <origin rpy="0 0 0" xyz="0 0 0"/>
    <parent link="ati_qc110m_tool0"/>
    <child link="ati_qc110f_base_link"/>
  </joint>
  <joint name="ati_m_pushcorp_ati_dock_joint" type="fixed">
    <origin rpy="0 0 0" xyz="0 0 0"/>
    <parent link="ati_qc110f_tool0"/>
    <child link="ati_dock_base_link"/>
  </joint>
  <joint name="ati_dock_pushcorp_afd_joint" type="fixed">
    <origin rpy="0 0 0" xyz="0 0 0"/>
    <parent link="ati_dock_tool0"/>
    <child link="pushcorp_afd620_base_link"/>
  </joint>
  <joint name="pushcorp_afd_stc_parallel_joint" type="fixed">
    <origin rpy="0 0 0" xyz="0 0 0"/>
    <parent link="pushcorp_afd620_tool0"/>
    <child link="pushcorp_stc1015_base_link"/>
  </joint>
  <joint name="positioner_part_joint" type="fixed">
    <!--      <origin xyz="-0.4 -1.1 -0.2" rpy="0 -0.523599 0" />-->
    <origin rpy="0 0 0" xyz="-0.55 -1.1 0"/>
    <parent link="positioner_tool0"/>
    <child link="part_link"/>
  </joint>
  <joint name="bt30_sander_joint" type="fixed">
    <origin rpy="0 0 0" xyz="0 0 0"/>
    <parent link="pushcorp_stc1015_tool0"/>
    <child link="st_base_link"/>
  </joint>
  <joint name="fence_panel1_joint" type="fixed">
    <origin rpy="0 0 -1.5708" xyz="-2.0 0 0"/>
    <parent link="world"/>
    <child link="fence_panel1_base_link"/>
  </joint>
  <joint name="fence_panel2_joint" type="fixed">
    <origin rpy="0 0 3.14159" xyz="0 0 0"/>
    <parent link="fence_panel1_base_link"/>
    <child link="fence_panel2_base_link"/>
  </joint>
  <joint name="fence_panel3_joint" type="fixed">
    <origin rpy="0 0 1.5708" xyz="0.025 -0.025 0"/>
    <parent link="fence_panel1_tool0"/>
    <child link="fence_panel3_base_link"/>
  </joint>
  <joint name="fence_panel4_joint" type="fixed">
    <origin rpy="0 0 -1.5708" xyz="0.025 -0.025 0"/>
    <parent link="fence_panel2_tool0"/>
    <child link="fence_panel4_base_link"/>
  </joint>
  <joint name="fence_panel5_joint" type="fixed">
    <origin rpy="0 0 0" xyz="0 0 0"/>
    <parent link="fence_panel3_tool0"/>
    <child link="fence_panel5_base_link"/>
  </joint>
  <joint name="fence_panel6_joint" type="fixed">
    <origin rpy="0 0 0" xyz="0 0 0"/>
    <parent link="fence_panel4_tool0"/>
    <child link="fence_panel6_base_link"/>
  </joint>
  <joint name="logo_joint" type="fixed">
    <origin rpy="1.5708 0 3.14159" xyz="0.9 0 2.3"/>
    <parent link="fence_panel1_base_link"/>
    <child link="logo_base_link"/>
  </joint>
  <!-- end of joint list -->
</robot>

